{
    "registryname": "cosmic_forge",
    "localizedname": "寰宇熔炉",
    "requires-blueprint": false,
    "failure-action": "still",
    "has-factory": true,
    "factory-only": true,
    "color": "424242",
    "modifiers": [
        {
            "elements": "modularmachinery:blockcasing@1",
            "x": 0,
            "y": -1,
            "z": 0,
            "description": "将控制器下方紧挨着的方块换成此方块以降低配方制作时间至75%！",
            "modifier": {
                "io": "output",
                "target": "duration",
                "operation": 1,
                "multiplier": 0.75
            }
        },
        {
            "elements": "modularmachinery:blockcasing@2",
            "x": 0,
            "y": -1,
            "z": 0,
            "description": "将控制器下方紧挨着的方块换成此方块以降低配方制作时间至66%！",
            "modifier": {
                "io": "output",
                "target": "duration",
                "operation": 1,
                "multiplier": 0.66
            }
        },
        {
            "elements": "modularmachinery:blockcasing@3",
            "x": 0,
            "y": -1,
            "z": 0,
            "description": "将控制器下方紧挨着的方块换成此方块以降低配方制作时间至50%！",
            "modifier": {
                "io": "output",
                "target": "duration",
                "operation": 1,
                "multiplier": 0.5
            }
        },
        {
            "elements": "modularmachinery:blockcasing@5",
            "x": 0,
            "y": -1,
            "z": 0,
            "description": "将控制器下方紧挨着的方块换成此方块以降低配方制作时间至33%！",
            "modifier": {
                "io": "output",
                "target": "duration",
                "operation": 1,
                "multiplier": 0.33
            }
        }
    ],
    "parts": [
        {
            "x": 0,
            "y": 0,
            "z": 0,
            "elements": [
                "modularmachinery:blockcontroller@2"
            ]
        },
        {
            "x": -2,
            "y": 0,
            "z": 2,
            "elements": [
                "additions:chromasteel_block@0"
            ]
        },
        {
            "x": -1,
            "y": 2,
            "z": 3,
            "elements": [
                "additions:infernium_block@0"
            ]
        },
        {
            "x": -1,
            "y": 0,
            "z": 0,
            "elements": "casings_all"
        },
        {
            "x": 1,
            "y": 2,
            "z": 1,
            "elements": [
                "additions:infernium_block@0"
            ]
        },
        {
            "x": 2,
            "y": 2,
            "z": 1,
            "elements": [
                "draconicevolution:infused_obsidian"
            ]
        },
        {
            "x": 1,
            "y": 0,
            "z": 0,
            "elements": "casings_all"
        },
        {
            "x": 1,
            "y": 2,
            "z": 3,
            "elements": [
                "additions:infernium_block@0"
            ]
        },
        {
            "x": 2,
            "y": 2,
            "z": 3,
            "elements": [
                "draconicevolution:infused_obsidian"
            ]
        },
        {
            "x": -1,
            "y": 0,
            "z": 4,
            "elements": "casings_all"
        },
        {
            "x": 2,
            "y": 0,
            "z": 2,
            "elements": [
                "additions:chromasteel_block@0"
            ]
        },
        {
            "x": 0,
            "y": 0,
            "z": 4,
            "elements": [
                "additions:chromasteel_block@0"
            ]
        },
        {
            "x": 1,
            "y": 0,
            "z": 4,
            "elements": "casings_all"
        },
        {
            "x": -2,
            "y": 3,
            "z": 1,
            "elements": [
                "draconicevolution:infused_obsidian"
            ]
        },
        {
            "x": 1,
            "y": -1,
            "z": 0,
            "elements": ["modularmachinery:blockcasing@4"]
        },
        {
            "x": 0,
            "y": -1,
            "z": 0,
            "elements": ["modularmachinery:blockcasing@4"]
        },
        {
            "x": -1,
            "y": 1,
            "z": 0,
            "elements": [
                "draconicevolution:infused_obsidian"
            ]
        },
        {
            "x": -2,
            "y": 3,
            "z": 3,
            "elements": [
                "draconicevolution:infused_obsidian"
            ]
        },
        {
            "x": 0,
            "y": 1,
            "z": 0,
            "elements": [
                "draconicevolution:infused_obsidian"
            ]
        },
        {
            "x": -1,
            "y": -1,
            "z": 0,
            "elements": ["modularmachinery:blockcasing@4"]
        },
        {
            "x": -2,
            "y": 1,
            "z": 2,
            "elements": [
                "draconicevolution:infused_obsidian"
            ]
        },
        {
            "x": -2,
            "y": -1,
            "z": 1,
            "elements": ["modularmachinery:blockcasing@4"]
        },
        {
            "x": 2,
            "y": 3,
            "z": 1,
            "elements": [
                "draconicevolution:infused_obsidian"
            ]
        },
        {
            "x": 1,
            "y": 1,
            "z": 0,
            "elements": [
                "draconicevolution:infused_obsidian"
            ]
        },
        {
            "x": 0,
            "y": 1,
            "z": 2,
            "elements": [
                "tconevo:metal_block@2"
            ]
        },
        {
            "x": -1,
            "y": -1,
            "z": 1,
            "elements": ["modularmachinery:blockcasing@4"]
        },
        {
            "x": 0,
            "y": -1,
            "z": 1,
            "elements": ["modularmachinery:blockcasing@4"]
        },
        {
            "x": -2,
            "y": -1,
            "z": 3,
            "elements": ["modularmachinery:blockcasing@4"]
        },
        {
            "x": -1,
            "y": 1,
            "z": 4,
            "elements": [
                "draconicevolution:infused_obsidian"
            ]
        },
        {
            "x": 2,
            "y": 3,
            "z": 3,
            "elements": [
                "draconicevolution:infused_obsidian"
            ]
        },
        {
            "x": 0,
            "y": 1,
            "z": 4,
            "elements": [
                "draconicevolution:infused_obsidian"
            ]
        },
        {
            "x": 2,
            "y": 1,
            "z": 2,
            "elements": [
                "draconicevolution:infused_obsidian"
            ]
        },
        {
            "x": 1,
            "y": -1,
            "z": 1,
            "elements": ["modularmachinery:blockcasing@4"]
        },
        {
            "x": -1,
            "y": -1,
            "z": 3,
            "elements": ["modularmachinery:blockcasing@4"]
        },
        {
            "x": 0,
            "y": -1,
            "z": 3,
            "elements": ["modularmachinery:blockcasing@4"]
        },
        {
            "x": 1,
            "y": 1,
            "z": 4,
            "elements": [
                "draconicevolution:infused_obsidian"
            ]
        },
        {
            "x": 2,
            "y": -1,
            "z": 1,
            "elements": ["modularmachinery:blockcasing@4"]
        },
        {
            "x": 1,
            "y": -1,
            "z": 3,
            "elements": ["modularmachinery:blockcasing@4"]
        },
        {
            "x": 2,
            "y": -1,
            "z": 3,
            "elements": ["modularmachinery:blockcasing@4"]
        },
        {
            "x": -1,
            "y": 4,
            "z": 1,
            "elements": [
                "additions:titanium_block@0"
            ]
        },
        {
            "x": -1,
            "y": 2,
            "z": 0,
            "elements": [
                "draconicevolution:infused_obsidian"
            ]
        },
        {
            "x": 0,
            "y": 4,
            "z": 1,
            "elements": [
                "additions:titanium_block@0"
            ]
        },
        {
            "x": 1,
            "y": 4,
            "z": 1,
            "elements": [
                "additions:titanium_block@0"
            ]
        },
        {
            "x": 0,
            "y": 2,
            "z": 0,
            "elements": "iron_bars"
        },
        {
            "x": -2,
            "y": 2,
            "z": 2,
            "elements": "iron_bars"
        },
        {
            "x": -1,
            "y": 4,
            "z": 3,
            "elements": [
                "additions:titanium_block@0"
            ]
        },
        {
            "x": -2,
            "y": 0,
            "z": 1,
            "elements": "casings_all"
        },
        {
            "x": 0,
            "y": 4,
            "z": 3,
            "elements": [
                "additions:titanium_block@0"
            ]
        },
        {
            "x": 1,
            "y": 2,
            "z": 0,
            "elements": [
                "draconicevolution:infused_obsidian"
            ]
        },
        {
            "x": 1,
            "y": 4,
            "z": 3,
            "elements": [
                "additions:titanium_block@0"
            ]
        },
        {
            "x": -1,
            "y": 0,
            "z": 1,
            "elements": [
                "additions:infernium_block@0"
            ]
        },
        {
            "x": -2,
            "y": 0,
            "z": 3,
            "elements": "casings_all"
        },
        {
            "x": -1,
            "y": 2,
            "z": 4,
            "elements": [
                "draconicevolution:infused_obsidian"
            ]
        },
        {
            "x": 0,
            "y": 2,
            "z": 4,
            "elements": "iron_bars"
        },
        {
            "x": 2,
            "y": 2,
            "z": 2,
            "elements": "iron_bars"
        },
        {
            "x": 1,
            "y": 0,
            "z": 1,
            "elements": [
                "additions:infernium_block@0"
            ]
        },
        {
            "x": -1,
            "y": 0,
            "z": 3,
            "elements": [
                "additions:infernium_block@0"
            ]
        },
        {
            "x": 2,
            "y": 0,
            "z": 1,
            "elements": "casings_all"
        },
        {
            "x": 1,
            "y": 2,
            "z": 4,
            "elements": [
                "draconicevolution:infused_obsidian"
            ]
        },
        {
            "x": 1,
            "y": 0,
            "z": 3,
            "elements": [
                "additions:infernium_block@0"
            ]
        },
        {
            "x": 2,
            "y": 0,
            "z": 3,
            "elements": "casings_all"
        },
        {
            "x": -1,
            "y": 3,
            "z": 0,
            "elements": [
                "draconicevolution:infused_obsidian"
            ]
        },
        {
            "x": -2,
            "y": 3,
            "z": 2,
            "elements": [
                "draconicevolution:draconic_block@0"
            ]
        },
        {
            "x": 0,
            "y": 3,
            "z": 0,
            "elements": [
                "draconicevolution:draconic_block@0"
            ]
        },
        {
            "x": 1,
            "y": 3,
            "z": 0,
            "elements": [
                "draconicevolution:infused_obsidian"
            ]
        },
        {
            "x": -2,
            "y": 1,
            "z": 1,
            "elements": [
                "draconicevolution:infused_obsidian"
            ]
        },
        {
            "x": -2,
            "y": 1,
            "z": 3,
            "elements": [
                "draconicevolution:infused_obsidian"
            ]
        },
        {
            "x": -1,
            "y": 3,
            "z": 4,
            "elements": [
                "draconicevolution:infused_obsidian"
            ]
        },
        {
            "x": -2,
            "y": -1,
            "z": 2,
            "elements": ["modularmachinery:blockcasing@4"]
        },
        {
            "x": 0,
            "y": 3,
            "z": 4,
            "elements": [
                "draconicevolution:draconic_block@0"
            ]
        },
        {
            "x": 2,
            "y": 3,
            "z": 2,
            "elements": [
                "draconicevolution:draconic_block@0"
            ]
        },
        {
            "x": 1,
            "y": 3,
            "z": 4,
            "elements": [
                "draconicevolution:infused_obsidian"
            ]
        },
        {
            "x": 2,
            "y": 1,
            "z": 1,
            "elements": [
                "draconicevolution:infused_obsidian"
            ]
        },
        {
            "x": -1,
            "y": -1,
            "z": 2,
            "elements": ["modularmachinery:blockcasing@4"]
        },
        {
            "x": 0,
            "y": -1,
            "z": 2,
            "elements": ["modularmachinery:blockcasing@4"]
        },
        {
            "x": 2,
            "y": 1,
            "z": 3,
            "elements": [
                "draconicevolution:infused_obsidian"
            ]
        },
        {
            "x": 1,
            "y": -1,
            "z": 2,
            "elements": ["modularmachinery:blockcasing@4"]
        },
        {
            "x": -1,
            "y": -1,
            "z": 4,
            "elements": ["modularmachinery:blockcasing@4"]
        },
        {
            "x": 0,
            "y": -1,
            "z": 4,
            "elements": ["modularmachinery:blockcasing@4"]
        },
        {
            "x": 2,
            "y": -1,
            "z": 2,
            "elements": ["modularmachinery:blockcasing@4"]
        },
        {
            "x": 1,
            "y": -1,
            "z": 4,
            "elements": ["modularmachinery:blockcasing@4"]
        },
        {
            "x": -2,
            "y": 2,
            "z": 1,
            "elements": [
                "draconicevolution:infused_obsidian"
            ]
        },
        {
            "x": -1,
            "y": 4,
            "z": 2,
            "elements": [
                "additions:titanium_block@0"
            ]
        },
        {
            "x": -1,
            "y": 2,
            "z": 1,
            "elements": [
                "additions:infernium_block@0"
            ]
        },
        {
            "x": 0,
            "y": 4,
            "z": 2,
            "elements": [
                "additions:cryonium_block@0"
            ]
        },
        {
            "x": 1,
            "y": 4,
            "z": 2,
            "elements": [
                "additions:titanium_block@0"
            ]
        },
        {
            "x": -2,
            "y": 2,
            "z": 3,
            "elements": [
                "draconicevolution:infused_obsidian"
            ]
        }
    ]
}
