{
    "registryname": "exp_power_generator",
    "localizedname": "经验发电机",
    "requires-blueprint": false,
    "failure-action": "still",
    "has-factory": true,
    "factory-only": true,
    "color": "76ff03",
    "modifiers": [
        {
            "elements": "modularmachinery:blockcasing@1",
            "x": 0,
            "y": 1,
            "z": 0,
            "description": "将控制器上方的紧挨着的方块换成此方块以增加25%电量产出！",
            "modifier": {
                "io": "output",
                "target": "energy",
                "operation": 1,
                "multiplier": 1.25
            }
        },
        {
            "elements": "modularmachinery:blockcasing@2",
            "x": 0,
            "y": 1,
            "z": 0,
            "description": "将控制器上方的紧挨着的方块换成此方块以增加50%电量产出！",
            "modifier": {
                "io": "output",
                "target": "energy",
                "operation": 1,
                "multiplier": 1.5
            }
        },
        {
            "elements": "modularmachinery:blockcasing@3",
            "x": 0,
            "y": 1,
            "z": 0,
            "description": "将控制器上方的紧挨着的方块换成此方块以增加100%电量产出！",
            "modifier": {
                "io": "output",
                "target": "energy",
                "operation": 1,
                "multiplier": 2.0
            }
        },
        {
            "elements": "modularmachinery:blockcasing@5",
            "x": 0,
            "y": 1,
            "z": 0,
            "description": "将控制器上方的紧挨着的方块换成此方块以增加150%电量产出！",
            "modifier": {
                "io": "output",
                "target": "energy",
                "operation": 1,
                "multiplier": 2.5
            }
        }
    ],
    "parts": [
        {
            "x": 0,
            "y": 0,
            "z": 0,
            "elements": [
                "modularmachinery:blockcontroller@2"
            ]
        },
        {
            "x": -1,
            "y": 0,
            "z": 0,
            "elements": "casings_all"
        },
        {
            "x": 1,
            "y": 1,
            "z": 0,
            "elements": ["additions:experience_block@0"]
        },
        {
            "x": -1,
            "y": 0,
            "z": 1,
            "elements": ["additions:compressed_experience_block@0"]
        },
        {
            "x": -1,
            "y": 1,
            "z": 2,
            "elements": ["additions:experience_block@0"]
        },
        {
            "x": 0,
            "y": 1,
            "z": 1,
            "elements": ["modularmachinery:blockcasing@0"]
        },
        {
            "x": -1,
            "y": -1,
            "z": 1,
            "elements": ["modularmachinery:blockcasing@0"]
        },
        {
            "x": 1,
            "y": 0,
            "z": 0,
            "elements": "casings_all"
        },
        {
            "x": -1,
            "y": 0,
            "z": 2,
            "elements": "casings_all"
        },
        {
            "x": 0,
            "y": 1,
            "z": 2,
            "elements": ["modularmachinery:blockcasing@0"]
        },
        {
            "x": 1,
            "y": 1,
            "z": 1,
            "elements": ["modularmachinery:blockcasing@0"]
        },
        {
            "x": 1,
            "y": 0,
            "z": 1,
            "elements": ["additions:compressed_experience_block@0"]
        },
        {
            "x": 0,
            "y": 0,
            "z": 2,
            "elements": ["additions:compressed_experience_block@0"]
        },
        {
            "x": -1,
            "y": -1,
            "z": 2,
            "elements": ["additions:experience_block@0"]
        },
        {
            "x": 1,
            "y": 1,
            "z": 2,
            "elements": ["additions:experience_block@0"]
        },
        {
            "x": 0,
            "y": -1,
            "z": 2,
            "elements": ["modularmachinery:blockcasing@0"]
        },
        {
            "x": 0,
            "y": -1,
            "z": 1,
            "elements": ["modularmachinery:blockcasing@0"]
        },
        {
            "x": 1,
            "y": -1,
            "z": 1,
            "elements": ["modularmachinery:blockcasing@0"]
        },
        {
            "x": 1,
            "y": 0,
            "z": 2,
            "elements": "casings_all"
        },
        {
            "x": 1,
            "y": -1,
            "z": 2,
            "elements": ["additions:experience_block@0"]
        },
        {
            "x": 1,
            "y": -1,
            "z": 0,
            "elements": ["additions:experience_block@0"]
        },
        {
            "x": -1,
            "y": 1,
            "z": 0,
            "elements": ["additions:experience_block@0"]
        },
        {
            "x": 0,
            "y": -1,
            "z": 0,
            "elements": ["modularmachinery:blockcasing@0"]
        },
        {
            "x": -1,
            "y": 1,
            "z": 1,
            "elements": ["modularmachinery:blockcasing@0"]
        },
        {
            "x": -1,
            "y": -1,
            "z": 0,
            "elements": ["additions:experience_block@0"]
        },
        {
            "x": 0,
            "y": 1,
            "z": 0,
            "elements": ["modularmachinery:blockcasing@0"]
        }
    ]
}
